DEBUG    urllib3.connectionpool:connectionpool.py:232 Starting new HTTP connection (1): 127.0.0.1:5000
DEBUG    urllib3.connectionpool:connectionpool.py:465 http://127.0.0.1:5000 "POST /user_login HTTP/1.1" 200 37
ERROR    root:test_login.py:43 测试失败，期望结果为:{'code': 1000, 'msg': '登录成功'},实际结果为:{'code': 1000, 'msg': '登录成功'}
ERROR    root:test_login.py:44 assert '登录成功' == {'code': 1000, 'msg': '登录成功'}
Traceback (most recent call last):
  File "D:\TDpytest\test_cases\test_business\test_login\test_login.py", line 39, in test_login
    assert res['msg'] == case['expect']
AssertionError: assert '登录成功' == {'code': 1000, 'msg': '登录成功'}